Workbook

Sheet Avg Factors Summary
A1: Average
B2: Resultant Driver Head a / Vehicle Peak a | C2: Resultant Driver Chest a / Vehicle Peak a | D2: Resultant Passenger Head a / Vehicle Peak a | E2: Resultant Passenger Chest a / Vehicle Peak a | F2: Resultant Passenger Pelvis a / Vehicle Peak a | G2: Driver Head a x / Head a r | H2: Driver Head a y / Head a r | I2: Driver Head a z / Head a r | J2: Driver Chest a x / Chest a r | K2: Driver Chest a y / Chest a r | L2: Driver Chest a z / Chest a r | M2: Passenger Head a x / Head a r | N2: Passenger Head a y / Head a r | O2: Passenger Head a z / Head a r | P2: Passenger Chest a x / Chest a r | Q2: Passenger Chest a y / Chest a r | R2: Passenger Chest a z / Chest a r | S2: Passenger Pelvis a x / Pelvis a r | T2: Passenger Pelvis a y / Pelvis a r | U2: Passenger Pelvis a z / Pelvis a r
A3: Car | B3: =Car!AP256 -> 1.522913 | C3: =Car!AQ256 -> 1.0481131 | D3: =Car!AR256 -> 1.4118231 | E3: =Car!AS256 -> 1.0674032 | F3: =Car!AT256 -> 1.1510267 | G3: =Car!AU256 -> 0.87579676 | H3: =Car!AV256 -> 0.36791619 | I3: =Car!AW256 -> 0.48197528 | ... U3: =Car!BI256 -> 0.68265524
A4: SUV | B4: =SUV!AP243 -> 1.2749581 | C4: =SUV!AQ243 -> 0.97140292 | D4: =SUV!AR243 -> 1.4369602 | E4: =SUV!AS243 -> 1.0788362 | F4: =SUV!AT243 -> 1.1549655 | G4: =SUV!AU243 -> 0.86028175 | H4: =SUV!AV243 -> 0.36013238 | I4: =SUV!AW243 -> 0.50659395 | ... U4: =SUV!BI243 -> 0.62901713
A5: Minivan | B5: =Minivan!AP24 -> 1.832815 | C5: =Minivan!AQ24 -> 1.2670827 | D5: =Minivan!AR24 -> 2.2846727 | E5: =Minivan!AS24 -> 1.2872725 | F5: =Minivan!AT24 -> 1.3889568 | G5: =Minivan!AU24 -> 0.90224266 | H5: =Minivan!AV24 -> 0.31170804 | I5: =Minivan!AW24 -> 0.44727251 | ... U5: =Minivan!BI24 -> 0.68158546
A6: Pickup | B6: =Pickup!AP53 -> 1.455024 | C6: =Pickup!AQ53 -> 0.90730213 | D6: =Pickup!AR53 -> 1.5286719 | E6: =Pickup!AS53 -> 1.0523494 | F6: =Pickup!AT53 -> 1.0474313 | G6: =Pickup!AU53 -> 0.85720855 | H6: =Pickup!AV53 -> 0.34131168 | I6: =Pickup!AW53 -> 0.46004067 | ... U6: =Pickup!BI53 -> 0.54582134
A7: All groups | B7: ='All Data'!AP567 -> 1.4229207 | C7: ='All Data'!AQ567 -> 1.0111403 | D7: ='All Data'!AR567 -> 1.460149 | E7: ='All Data'!AS567 -> 1.077759 | F7: ='All Data'!AT567 -> 1.1474474 | G7: ='All Data'!AU567 -> 0.86853142 | H7: ='All Data'!AV567 -> 0.36015252 | I7: ='All Data'!AW567 -> 0.48921463 | ... U7: ='All Data'!BI567 -> 0.6348691
A9: St dev
A10: Car | B10: =Car!AP257 -> 1.0703246 | C10: =Car!AQ257 -> 0.24290074 | D10: =Car!AR257 -> 0.57749348 | E10: =Car!AS257 -> 0.47594096 | F10: =Car!AT257 -> 0.30057049 | G10: =Car!AU257 -> 0.10104038 | H10: =Car!AV257 -> 0.1774765 | I10: =Car!AW257 -> 0.13690347 | ... U10: =Car!BI257 -> 0.12394925
A11: SUV | B11: =SUV!AP244 -> 0.51840162 | C11: =SUV!AQ244 -> 0.2380649 | D11: =SUV!AR244 -> 0.43634103 | E11: =SUV!AS244 -> 0.35080688 | F11: =SUV!AT244 -> 0.29403288 | G11: =SUV!AU244 -> 0.10334395 | H11: =SUV!AV244 -> 0.16380365 | I11: =SUV!AW244 -> 0.14250088 | ... U11: =SUV!BI244 -> 0.12425068
A12: Minivan | B12: =Minivan!AP25 -> 0.71425005 | C12: =Minivan!AQ25 -> 0.15780878 | D12: =Minivan!AR25 -> 0.77947815 | E12: =Minivan!AS25 -> 0.20791914 | F12: =Minivan!AT25 -> 0.22863624 | G12: =Minivan!AU25 -> 0.077427419 | H12: =Minivan!AV25 -> 0.17797226 | I12: =Minivan!AW25 -> 0.12410303 | ... U12: =Minivan!BI25 -> 0.13482542
A13: Pickup | B13: =Pickup!AP54 -> 0.8127867 | C13: =Pickup!AQ54 -> 0.24633662 | D13: =Pickup!AR54 -> 0.46168328 | E13: =Pickup!AS54 -> 0.2903788 | F13: =Pickup!AT54 -> 0.32919599 | G13: =Pickup!AU54 -> 0.15856084 | H13: =Pickup!AV54 -> 0.18414605 | I13: =Pickup!AW54 -> 0.17413264 | ... U13: =Pickup!BI54 -> 0.11302099
A14: All groups | B14: ='All Data'!AP568 -> 0.85009254 | C14: ='All Data'!AQ568 -> 0.24763373 | D14: ='All Data'!AR568 -> 0.50152754 | E14: ='All Data'!AS568 -> 0.3784323 | F14: ='All Data'!AT568 -> 0.30073976 | G14: ='All Data'!AU568 -> 0.10775458 | H14: ='All Data'!AV568 -> 0.17237026 | I14: ='All Data'!AW568 -> 0.14314064 | ... U14: ='All Data'!BI568 -> 0.12851577

Sheet Plots
A1: Driver ax / ar
A2: Avg
B3: Car | C3: SUV | D3: Minivan | E3: Pickup | F3: All Data
A4: Head | B4: 0.87579676 | C4: 0.86028175 | D4: 0.90224266 | E4: 0.85720855 | F4: 0.86853142
A5: Chest | B5: 0.92905925 | C5: 0.9259493 | D5: 0.93420905 | E5: 0.92048541 | F5: 0.92716752
A7: St dev
B8: Car | C8: SUV | D8: Minivan | E8: Pickup | F8: All Data
A9: Head | B9: 0.10104038 | C9: 0.10334395 | D9: 0.077427419 | E9: 0.15856084 | F9: 0.10775458
A10: Chest | B10: 0.040102279 | C10: 0.046386776 | D10: 0.040184257 | E10: 0.059333404 | F10: 0.044778155
A12: Label
B13: Car | C13: SUV | D13: Minivan | E13: Pickup | F13: All Data
A14: Head | B14: =ROUND(B4,2) & " ± " & ROUND(B9,2) -> 0.88 ± 0.1 | C14: =ROUND(C4,2) & " ± " & ROUND(C9,2) -> 0.86 ± 0.1 | D14: =ROUND(D4,2) & " ± " & ROUND(D9,2) -> 0.9 ± 0.08 | E14: =ROUND(E4,2) & " ± " & ROUND(E9,2) -> 0.86 ± 0.16 | F14: =ROUND(F4,2) & " ± " & ROUND(F9,2) -> 0.87 ± 0.11
A15: Chest | B15: =ROUND(B5,2) & " ± " & ROUND(B10,2) -> 0.93 ± 0.04 | C15: =ROUND(C5,2) & " ± " & ROUND(C10,2) -> 0.93 ± 0.05 | D15: =ROUND(D5,2) & " ± " & ROUND(D10,2) -> 0.93 ± 0.04 | E15: =ROUND(E5,2) & " ± " & ROUND(E10,2) -> 0.92 ± 0.06 | F15: =ROUND(F5,2) & " ± " & ROUND(F10,2) -> 0.93 ± 0.04
A17: Passenger ax / ar
A18: Avg
B19: Car | C19: SUV | D19: Minivan | E19: Pickup | F19: All Data
A20: Head | B20: 0.64190731 | C20: 0.59978978 | D20: 0.67633456 | E20: 0.70123535 | F20: 0.62364231
A21: Chest | B21: 0.7276181 | C21: 0.72914931 | D21: 0.86795056 | E21: 0.73853294 | F21: 0.73299016
A22: Pelvis | B22: 0.76380758 | C22: 0.7886339 | D22: 0.79481182 | E22: 0.85577787 | F22: 0.78979552
A24: St dev
B25: Car | C25: SUV | D25: Minivan | E25: Pickup | F25: All Data
A26: Head | B26: 0.17310878 | C26: 0.15940714 | D26: 0.22532778 | E26: 0.13017866 | F26: 0.16417555
A27: Chest | B27: 0.16572869 | C27: 0.15707355 | D27: 0.08140616 | E27: 0.15679005 | F27: 0.158552
A28: Pelvis | B28: 0.10633726 | C28: 0.084358637 | D28: 0.13487941 | E28: 0.074303545 | F28: 0.093702904
A30: Label
B31: Car | C31: SUV | D31: Minivan | E31: Pickup | F31: All Data
A32: Head | B32: =ROUND(B20,2) & " ± " & ROUND(B26,2) -> 0.64 ± 0.17 | C32: =ROUND(C20,2) & " ± " & ROUND(C26,2) -> 0.6 ± 0.16 | D32: =ROUND(D20,2) & " ± " & ROUND(D26,2) -> 0.68 ± 0.23 | E32: =ROUND(E20,2) & " ± " & ROUND(E26,2) -> 0.7 ± 0.13 | F32: =ROUND(F20,2) & " ± " & ROUND(F26,2) -> 0.62 ± 0.16
A33: Chest | B33: =ROUND(B21,2) & " ± " & ROUND(B27,2) -> 0.73 ± 0.17 | C33: =ROUND(C21,2) & " ± " & ROUND(C27,2) -> 0.73 ± 0.16 | D33: =ROUND(D21,2) & " ± " & ROUND(D27,2) -> 0.87 ± 0.08 | E33: =ROUND(E21,2) & " ± " & ROUND(E27,2) -> 0.74 ± 0.16 | F33: =ROUND(F21,2) & " ± " & ROUND(F27,2) -> 0.73 ± 0.16
A34: Pelvis | B34: =ROUND(B22,2) & " ± " & ROUND(B28,2) -> 0.76 ± 0.11 | C34: =ROUND(C22,2) & " ± " & ROUND(C28,2) -> 0.79 ± 0.08 | D34: =ROUND(D22,2) & " ± " & ROUND(D28,2) -> 0.79 ± 0.13 | E34: =ROUND(E22,2) & " ± " & ROUND(E28,2) -> 0.86 ± 0.07 | F34: =ROUND(F22,2) & " ± " & ROUND(F28,2) -> 0.79 ± 0.09
A36: Driver ay / ar
A37: Avg
B38: Car | C38: SUV | D38: Minivan | E38: Pickup | F38: All Data
A39: Head | B39: 0.36791619 | C39: 0.36013238 | D39: 0.31170804 | E39: 0.34131168 | F39: 0.36015252
A40: Chest | B40: 0.36650963 | C40: 0.35050717 | D40: 0.34278339 | E40: 0.35918125 | F40: 0.35816697
A42: St dev
B43: Car | C43: SUV | D43: Minivan | E43: Pickup | F43: All Data
A44: Head | B44: 0.1774765 | C44: 0.16380365 | D44: 0.17797226 | E44: 0.18414605 | F44: 0.17237026
A45: Chest | B45: 0.088102649 | C45: 0.091147662 | D45: 0.079350454 | E45: 0.10566107 | F45: 0.090893734
A47: Label
B48: Car | C48: SUV | D48: Minivan | E48: Pickup | F48: All Data
...

Sheet Car
A1: Test ID | B1: Vehicle Info | C1: Vehicle Type | D1: ATD | E1: Vehicle Test Weight (kg) | F1: Vehicle dV (kph) | G1: Vehicle Peak a (g) | H1: Vehicle Peak F (N) | I1: Driver Head Peak a - x (g) | J1: Driver Head Peak a - y (g) | K1: Driver Head Peak a - z (g) | L1: Driver Head Peak a - R (g) | M1: Driver Chest Peak a - x (g) | N1: Driver Chest Peak a - y (g) | O1: Driver Chest Peak a - z (g) | P1: Driver Chest Peak a - R (g) | Q1: Driver Upper Neck Peak F - x (N) | R1: Driver Upper Neck Peak F - z Compression (N) | S1: Driver Upper Neck Peak F - z Tension (N) | T1: Driver Upper Neck Peak F - R (N) | U1: Passenger Head Peak a - x (g) | V1: Passenger Head Peak a - y (g) | W1: Passenger Head Peak a - z (g) | X1: Passenger Head Peak a - R (g) | Y1: Passenger Chest Peak a - x (g) | Z1: Passenger Chest Peak a - y (g) | AA1: Passenger Chest Peak a - z (g) | AB1: Passenger Chest Peak a - R (g) | AC1: Passenger Pelvis Peak a - x (g) | AD1: Passenger Pelvis Peak a - y (g) | AE1: Passenger Pelvis Peak a - z (g) | AF1: Passenger Pelvis Peak a - R (g) | AG1: Passenger Upper Neck Peak F - x (N) | AH1: Passenger Upper Neck Peak F - z Compression (N) | AI1: Passenger Upper Neck Peak F - z Tension (N) | AJ1: Passenger Upper Neck Peak F - R (N) | AK1: Passenger Lumbar Peak F - x (N) | AL1: Passenger Lumbar Peak F - z Compression (N) | AM1: Passenger Lumbar Peak F - z Tension (N) | AN1: Passenger Lumbar Peak F - R (N) | AP1: Resultant Driver Head a / Vehicle Peak a | AQ1: Resultant Driver Chest a / Vehicle Peak a | AR1: Resultant Passenger Head a / Vehicle Peak a | AS1: Resultant Passenger Chest a / Vehicle Peak a | AT1: Resultant Passenger Pelvis a / Vehicle Peak a | AU1: Driver Head a x / Head a r | AV1: Driver Head a y / Head a r | AW1: Driver Head a z / Head a r | AX1: Driver Chest a x / Chest a r | AY1: Driver Chest a y / Chest a r | AZ1: Driver Chest a z / Chest a r | BA1: Passenger Head a x / Head a r | BB1: Passenger Head a y / Head a r | BC1: Passenger Head a z / Head a r | BD1: Passenger Chest a x / Chest a r | BE1: Passenger Chest a y / Chest a r | BF1: Passenger Chest a z / Chest a r | BG1: Passenger Pelvis a x / Pelvis a r | BH1: Passenger Pelvis a y / Pelvis a r | BI1: Passenger Pelvis a z / Pelvis a r
A2: CEF0101 | B2: 2001 Lexus LS430 | C2: car (sedan) | D2: Hybrid III | E2: 1966 | F2: 75.7274 | G2: 55.5466 | H2: 109204.62 | I2: 39.2122 | J2: 17.7606 | K2: 25.6314 | L2: 44.5982 | M2: 42.7945 | N2: 15.8114 | O2: 28.8016 | P2: 44.7258 | Q2: 712.6574 | R2: 922.4075 | S2: 957.2598 | T2: 1002.1866 | AP2: 0.80289703 | AQ2: 0.8051942 | AU2: 0.87923279 | AV2: 0.3982358 | AW2: 0.57471826 | AX2: 0.95681911 | AY2: 0.35351855 | AZ2: 0.64395941
A3: CEF0103 | B3: 2001 Hyundai Elantra | C3: car (sedan) | D3: Hybrid III | E3: 1416 | F3: 68.8746 | G3: 41.3345 | H3: 58529.652 | I3: 91.3761 | J3: 13.7947 | K3: 51.0217 | L3: 99.9954 | M3: 51.994 | N3: 19.4996 | O3: 15.1982 | P3: 54.976 | Q3: 741.7878 | R3: 92.9685 | S3: 3354.849 | T3: 3400.5218 | AP3: 2.4191753 | AQ3: 1.330027 | AU3: 0.91380303 | AV3: 0.13795335 | AW3: 0.51024047 | AX3: 0.94575815 | AY3: 0.35469296 | AZ3: 0.27645154
A4: CEF0112 | B4: 2001 Hyundai Elantra | C4: car (sedan) | D4: Hybrid III | E4: 1415 | F4: 69.0223 | G4: 39.0666 | H4: 55279.239 | I4: 168.021 | J4: 27.6535 | K4: 44.8082 | L4: 173.8742 | M4: 49.6512 | N4: 17.2713 | O4: 17.0028 | P4: 52.2493 | Q4: 1659.776 | R4: 988.6149 | S4: 3191.9897 | T4: 3597.7291 | AP4: 4.4507124 | AQ4: 1.3374417 | AU4: 0.96633658 | AV4: 0.15904315 | AW4: 0.25770471 | AX4: 0.95027493 | AY4: 0.33055562 | AZ4: 0.3254168
A5: CEF0123 | B5: 2002 Mitsubishi Lancer | C5: car (sedan) | D5: Hybrid III | E5: 1370 | F5: 64.367241 | G5: 42.128527 | H5: 57716.082 | I5: 58.319689 | J5: 16.252885 | K5: 21.794421 | L5: 62.74418 | M5: 45.946365 | N5: 15.075847 | O5: 18.030319 | P5: 49.233038 | Q5: 735.46542 | R5: 366.98285 | S5: 2604.7835 | T5: 2672.2277 | AP5: 1.4893514 | AQ5: 1.168639 | AU5: 0.92948364 | AV5: 0.25903414 | AW5: 0.34735367 | AX5: 0.93324253 | AY5: 0.30621403 | AZ5: 0.36622398
A6: CEF0124 | B6: 2002 Volvo S40 | C6: car (sedan) | D6: Hybrid III | E6: 1460 | F6: 63.888387 | G6: 93.418446 | H6: 136390.93 | I6: 54.314808 | J6: 19.024229 | K6: 19.353985 | L6: 56.201106 | M6: 41.988201 | N6: 23.557304 | O6: 18.102251 | P6: 43.517394 | Q6: 441.3277 | R6: 35.665975 | S6: 2227.0083 | T6: 2228.6901 | AP6: 0.60160609 | AQ6: 0.46583299 | AU6: 0.96643664 | AV6: 0.33850275 | AW6: 0.34437018 | AX6: 0.96486019 | AY6: 0.54133076 | AZ6: 0.41597737
A7: CEF0126 | B7: 2002 Subaru Impreza | C7: car (sedan) | D7: Hybrid III | E7: 1474 | F7: 69.694766 | G7: 55.772489 | H7: 82208.649 | I7: 36.902098 | J7: 17.044696 | K7: 19.563598 | L7: 39.51867 | M7: 34.003306 | N7: 21.960337 | O7: 16.8048 | P7: 40.103577 | Q7: 353.82497 | R7: 120.70808 | S7: 1330.1745 | T7: 1341.136 | AP7: 0.70856924 | AQ7: 0.71905661 | AU7: 0.93378897 | AV7: 0.43130743 | AW7: 0.49504697 | AX7: 0.84788711 | AY7: 0.54759048 | AZ7: 0.41903494
A8: CEF0129 | B8: 2002 Lexus IS 300 | C8: car (sedan) | D8: Hybrid III | E8: 1644 | F8: 69.0002 | G8: 39.735256 | H8: 65324.761 | I8: 52.025121 | J8: 21.291087 | K8: 17.759541 | L8: 56.218528 | M8: 44.398736 | N8: 17.351341 | O8: 12.730338 | P8: 48.125674 | Q8: 614.49906 | R8: 223.66899 | S8: 1264.5672 | T8: 1340.3267 | AP8: 1.4148274 | AQ8: 1.211158 | AU8: 0.92540881 | AV8: 0.37872011 | AW8: 0.31590192 | AX8: 0.92255822 | AY8: 0.3605423 | AZ8: 0.2645228
A9: CEF0202 | B9: 2002 Toyota Camry | C9: car (sedan) | D9: Hybrid III | E9: 1586 | F9: 69.943709 | G9: 38.64979 | H9: 61298.567 | I9: 61.977768 | J9: 12.977299 | K9: 24.651796 | L9: 66.028035 | M9: 43.165027 | N9: 15.020104 | O9: 11.934235 | P9: 45.20556 | Q9: 423.55979 | R9: 1569.0361 | S9: 1848.8098 | T9: 1855.6603 | AP9: 1.7083672 | AQ9: 1.1696198 | AU9: 0.93865837 | AV9: 0.19654226 | AW9: 0.37335347 | AX9: 0.95486102 | AY9: 0.33226231 | AZ9: 0.26399927
A10: CEF0203 | B10: 2002 Nissan Altima | C10: car (sedan) | D10: Hybrid III | E10: 1538 | F10: 69.972559 | G10: 77.176966 | H10: 118698.17 | I10: 79.981238 | J10: 21.250065 | K10: 35.553389 | L10: 87.008299 | M10: 46.87035 | N10: 18.127036 | O10: 9.682163 | P10: 47.282227 | Q10: 565.38275 | R10: 2514.1205 | S10: 297.40767 | T10: 2530.6132 | AP10: 1.1273869 | AQ10: 0.61264687 | AU10: 0.91923689 | AV10: 0.24423032 | AW10: 0.40862067 | AX10: 0.99128897 | AY10: 0.38337949 | AZ10: 0.20477384
A11: CEF0204 | B11: 2002 Volvo S60 | C11: car (sedan) | D11: Hybrid III | E11: 1657 | F11: 70.672808 | G11: 53.670744 | H11: 88932.423 | I11: 43.694954 | J11: 14.026657 | K11: 19.815414 | L11: 48.109663 | M11: 42.909305 | N11: 14.670116 | O11: 14.491102 | P11: 45.315784 | Q11: 704.45899 | R11: 1271.7795 | S11: 73.064671 | T11: 1287.3003 | AP11: 0.89638524 | AQ11: 0.84432934 | AU11: 0.90823654 | AV11: 0.29155592 | AW11: 0.41188012 | AX11: 0.94689535 | AY11: 0.32373082 | AZ11: 0.31978045
A12: CEF0205 | B12: 2002 Hyundai XG 350 | C12: car (sedan) | D12: Hybrid III | E12: 1800 | F12: 67.394909 | G12: 38.079226 | H12: 68542.607 | I12: 50.394795 | J12: 16.137115 | K12: 24.136382 | L12: 55.331405 | M12: 48.371238 | N12: 18.965467 | O12: 7.910358 | P12: 51.552919 | Q12: 302.13657 | R12: 218.73953 | S12: 1518.3483 | T12: 1524.8385 | AP12: 1.4530601 | AQ12: 1.3538332 | AU12: 0.91078105 | AV12: 0.29164477 | AW12: 0.43621488 | AX12: 0.9382832 | AY12: 0.36788348 | AZ12: 0.15344152
A13: CEF0206 | B13: 2002 Acura TL | C13: car (sedan) | D13: Hybrid III | E13: 1690 | F13: 73.151397 | G13: 39.848762 | H13: 67344.408 | I13: 44.512658 | J13: 14.109515 | K13: 14.744401 | L13: 45.199557 | M13: 43.041033 | N13: 17.480389 | O13: 14.681293 | P13: 46.550034 | Q13: 322.62563 | R13: 1011.0912 | S13: 14.177753 | T13: 1011.1038 | AP13: 1.1342776 | AQ13: 1.1681676 | AU13: 0.98480297 | AV13: 0.31216047 | AW13: 0.32620676 | AX13: 0.92461872 | AY13: 0.37551829 | AZ13: 0.31538737
... A19: CEF0216 | B19: 2002 Audi A4 | C19: car (sedan) | D19: Hybrid III | E19: 1734 | F19: 70.64687 | G19: 39.935663 | H19: 69248.44 | I19: 34.847679 | J19: 31.550149 | K19: 19.943321 | L19: 40.544132 | M19: 41.207631 | N19: 18.875695 | O19: 9.491762 | P19: 45.230196 | Q19: 683.70213 | R19: 2241.7513 | S19: 998.44632 | T19: 2246.3166 | AP19: 1.0152362 | AQ19: 1.1325766 | AU19: 0.85949994 | AV19: 0.77816807 | AW19: 0.49189167 | AX19: 0.91106461 | AY19: 0.41732508 | AZ19: 0.20985454
A20: CEF0217 | B20: 2002 Suzuki Aerio | C20: car (sedan) | D20: Hybrid III | E20: 1330 | F20: 68.503431 | G20: 44.454549 | I20: 40.469712 | J20: 16.061263 | K20: 25.168837 | L20: 44.724475 | M20: 38.470739 | N20: 21.327196 | O20: 14.408384 | P20: 44.137829 | Q20: 561.49722 | R20: 2462.271 | S20: 1332.1547 | T20: 2519.9219 | AP20: 1.006072 | AQ20: 0.99287542 | AU20: 0.90486723 | AV20: 0.35911574 | AW20: 0.5627531 | AX20: 0.8716047 | AY20: 0.4831954 | AZ20: 0.3264407
A21: CEF0218 | B21: 2003 Toyota Corolla | C21: car (sedan) | D21: Hybrid III | E21: 1297 | F21: 67.587586 | G21: 52.001718 | H21: 67446.228 | I21: 41.237722 | J21: 12.868797 | K21: 25.581866 | L21: 42.153904 | M21: 51.233964 | N21: 15.985535 | O21: 18.511783 | P21: 52.247191 | Q21: 642.24842 | R21: 1436.5534 | S21: 438.96203 | T21: 1440.5295 | AP21: 0.81062522 | AQ21: 1.0047205 | AU21: 0.97826579 | AV21: 0.30528126 | AW21: 0.60686825 | AX21: 0.98060705 | AY21: 0.3059597 | AZ21: 0.35431155
A22: CEF0220 | B22: 2003 Honda Accord | C22: car (sedan) | D22: Hybrid III | E22: 1568 | F22: 70.42146 | G22: 36.797459 | H22: 57698.416 | I22: 56.857057 | J22: 12.08463 | K22: 17.185072 | L22: 57.040622 | M22: 40.089518 | N22: 12.863672 | O22: 9.287226 | P22: 41.299821 | Q22: 372.46072 | R22: 217.40879 | S22: 1669.9479 | T22: 1670.6751 | AP22: 1.5501239 | AQ22: 1.1223552 | AU22: 0.99678185 | AV22: 0.21186007 | AW22: 0.30127778 | AX22: 0.97069472 | AY22: 0.31147041 | AZ22: 0.22487327
A23: CEF0221 | B23: 2003 Cadillac CTS | C23: car (sedan) | D23: Hybrid III | E23: 1720 | F23: 75.664417 | G23: 49.829411 | H23: 85706.587 | I23: 48.177431 | J23: 12.185075 | K23: 21.481632 | L23: 49.60092 | M23: 56.772934 | N23: 16.778325 | O23: 14.155618 | P23: 58.599609 | Q23: 1254.7149 | R23: 2159.4414 | S23: 1210.8499 | T23: 2193.7724 | AP23: 0.99541454 | AQ23: 1.1760044 | AU23: 0.97130116 | AV23: 0.24566228 | AW23: 0.43308939 | AX23: 0.96882786 | AY23: 0.28632145 | AZ23: 0.24156506
A24: CEF0222 | B24: 2002 Mini Cooper | C24: car (hatchback) | D24: Hybrid III | E24: 1248 | F24: 66.860295 | G24: 50.285342 | H24: 62756.107 | I24: 41.540527 | J24: 27.693617 | K24: 25.849937 | L24: 47.584402 | M24: 44.072537 | N24: 18.252671 | O24: 16.438747 | P24: 48.291641 | Q24: 627.44654 | R24: 450.36777 | S24: 1657.2559 | T24: 1771.6235 | AP24: 0.94628773 | AQ24: 0.96035224 | AU24: 0.87298622 | AV24: 0.58198939 | AW24: 0.54324392 | AX24: 0.91263283 | AY24: 0.3779675 | AZ24: 0.34040564
A25: CEF0223 | B25: 2003 Toyota Corolla | C25: car (sedan) | D25: Hybrid III | E25: 1279 | F25: 71.024286 | G25: 40.290927 | H25: 51532.096 | I25: 43.443924 | J25: 17.147789 | K25: 24.786313 | L25: 46.255137 | M25: 44.12001 | N25: 15.624784 | O25: 10.850312 | P25: 46.048186 | Q25: 423.54782 | R25: 540.78845 | S25: 1272.3927 | T25: 1272.4057 | AP25: 1.1480286 | AQ25: 1.1428922 | AU25: 0.93922377 | AV25: 0.37072183 | AW25: 0.53586076 | AX25: 0.95812699 | AY25: 0.33931378 | AZ25: 0.23562952
A26: CEF0224 | B26: 2002 Acura RL | C26: car (sedan) | D26: Hybrid III | E26: 1849 | F26: 76.559346 | G26: 53.046541 | H26: 98083.054 | I26: 132.1401 | J26: 15.474986 | K26: 30.920573 | L26: 135.62388 | M26: 43.092936 | N26: 22.893444 | O26: 6.653842 | P26: 48.025039 | Q26: 574.68825 | R26: 14.092062 | S26: 1799.3947 | T26: 1803.0976 | AP26: 2.556696 | AQ26: 0.90533781 | AU26: 0.97431293 | AV26: 0.11410222 | AW26: 0.22798767 | AX26: 0.89730143 | AY26: 0.47669808 | AZ26: 0.13854943
A27: CEF0301 | B27: 2003 Lincoln Town Car | C27: car (sedan) | D27: Hybrid III | E27: 2074 | F27: 70.431141 | G27: 49.789961 | H27: 103264.38 | I27: 171.73192 | J27: 57.514998 | K27: 52.875328 | L27: 180.29387 | M27: 42.505638 | N27: 8.038161 | O27: 14.590057 | P27: 43.157347 | Q27: 1000.8133 | R27: 366.01572 | S27: 1361.4045 | T27: 1421.0425 | AP27: 3.6210888 | AQ27: 0.86678813 | AU27: 0.95251113 | AV27: 0.31900695 | AW27: 0.29327302 | AX27: 0.98489923 | AY27: 0.18625244 | AZ27: 0.33806659
A28: CEF0302 | B28: 2003 Infiniti Q45 | C28: car (sedan) | D28: Hybrid III | E28: 1914 | F28: 73.960032 | G28: 61.545643 | H28: 117798.36 | I28: 44.676578 | J28: 16.186173 | K28: 18.786593 | L28: 46.466085 | M28: 42.652141 | N28: 15.933148 | O28: 19.449876 | P28: 47.437705 | Q28: 535.15771 | R28: 190.23956 | S28: 969.2896 | T28: 1106.7621 | AP28: 0.75498578 | AQ28: 0.77077276 | AU28: 0.96148789 | AV28: 0.34834381 | AW28: 0.40430764 | AX28: 0.89911898 | AY28: 0.33587519 | AZ28: 0.41000879
A29: CEF0306 | B29: 2003 Saab 9-3 | C29: car (sedan) | D29: Hybrid III | E29: 1614 | F29: 70.786012 | G29: 34.165664 | H29: 55143.382 | I29: 30.164257 | J29: 22.877654 | K29: 26.467734 | L29: 44.321419 | M29: 42.921175 | N29: 17.474669 | O29: 12.811061 | P29: 46.095647 | Q29: 491.67858 | R29: 507.28276 | S29: 1134.0579 | T29: 1140.2121 | AP29: 1.2972503 | AQ29: 1.3491805 | AU29: 0.68057968 | AV29: 0.51617603 | AW29: 0.59717704 | AX29: 0.93113293 | AY29: 0.37909586 | AZ29: 0.27792344
A30: CEF0307 | B30: 2003 Infiniti G35 | C30: car (sedan) | D30: Hybrid III | E30: 1678 | F30: 72.023581 | G30: 51.394908 | H30: 86240.656 | I30: 78.765666 | J30: 19.165172 | K30: 18.11321 | L30: 80.239032 | M30: 51.716632 | N30: 20.272632 | O30: 17.537711 | P30: 54.715468 | Q30: 1418.1974 | R30: 265.87331 | S30: 1323.3272 | T30: 1639.1766 | AP30: 1.5612253 | AQ30: 1.0646087 | AU30: 0.98163779 | AV30: 0.23885099 | AW30: 0.22574063 | AX30: 0.94519217 | AY30: 0.37051007 | AZ30: 0.32052565
A31: CEF0308 | B31: 2003 Mercedes-Benz E 500 | C31: car (sedan) | D31: Hybrid III | E31: 1902 | F31: 70.907536 | G31: 62.269197 | H31: 118436.01 | I31: 46.673404 | J31: 17.473669 | K31: 30.62472 | L31: 50.545443 | M31: 58.367846 | N31: 17.366787 | O31: 11.813892 | P31: 58.915816 | Q31: 763.35543 | R31: 78.088595 | S31: 1434.7634 | T31: 1494.7425 | AP31: 0.81172466 | AQ31: 0.94614703 | AU31: 0.92339489 | AV31: 0.34570216 | AW31: 0.60588489 | AX31: 0.9906991 | AY31: 0.29477292 | AZ31: 0.20052157
A32: CEF0311 | B32: 2003 Mazda6 | C32: car (sedan) | D32: Hybrid III | E32: 1520 | F32: 71.403273 | G32: 38.363688 | H32: 58312.806 | I32: 56.508466 | J32: 49.539116 | K32: 30.464263 | L32: 78.965936 | M32: 39.276573 | N32: 15.021752 | O32: 9.372021 | P32: 42.016236 | Q32: 302.57135 | R32: 1151.5656 | S32: 988.95773 | T32: 1152.5318 | AP32: 2.058351 | AQ32: 1.0952085 | AU32: 0.7156056 | AV32: 0.62734792 | AW32: 0.38578993 | AX32: 0.93479513 | AY32: 0.35752255 | AZ32: 0.22305713
... A136: CEF1201 (Driver) | B136: 2012 Kia Rio | C136: car (hatchback) | D136: Hybrid III | E136: 1321 | F136: 68.425318 | G136: 51.191053 | H136: 67623.381 | I136: 41.273511 | J136: 13.144962 | K136: 34.285122 | L136: 52.43021 | M136: 37.520608 | N136: 12.69459 | O136: 16.632852 | P136: 41.343339 | Q136: 556.90533 | R136: 1103.3223 | S136: 1692.8266 | T136: 1773.0511 | AP136: 1.0242065 | AQ136: 0.80762822 | AU136: 0.78720857 | AV136: 0.2507135 | AW136: 0.65391923 | AX136: 0.90753696 | AY136: 0.30705284 | AZ136: 0.40231032
A137: CEF1203 (Driver) | B137: 2012 Scion iQ | C137: car (hatchback) | D137: Hybrid III | E137: 1101 | F137: 63.100076 | G137: 61.362727 | I137: 51.406465 | J137: 21.920153 | K137: 31.492866 | L137: 62.483982 | M137: 33.404458 | N137: 31.221878 | O137: 16.096496 | P137: 39.253927 | Q137: 768.23939 | R137: 426.71358 | S137: 1454.8977 | T137: 1513.0996 | AP137: 1.0182726 | AQ137: 0.63970311 | AU137: 0.82271429 | AV137: 0.35081236 | AW137: 0.50401503 | AX137: 0.85098386 | AY137: 0.79538228 | AZ137: 0.41006077
A138: CEF1204 (Driver) | B138: 2013 Scion FR-S | C138: car (hatchback) | D138: Hybrid III | E138: 1394 | F138: 68.044024 | G138: 43.270454 | H138: 60319.012 | I138: 33.686874 | J138: 15.439147 | K138: 28.800896 | L138: 45.701309 | M138: 37.443149 | N138: 18.888899 | O138: 14.319163 | P138: 43.796191 | Q138: 566.91955 | R138: 133.85275 | S138: 993.14325 | T138: 1065.5238 | AP138: 1.0561782 | AQ138: 1.01215 | AU138: 0.73710962 | AV138: 0.33782725 | AW138: 0.63019849 | AX138: 0.85494076 | AY138: 0.4312909 | AZ138: 0.32694996
A139: CEF1205 (Driver) | B139: 2012 Toyota Prius Plug-in | C139: car (hatchback) | D139: Hybrid III | E139: 1578 | F139: 68.67524 | G139: 56.887004 | H139: 89767.692 | I139: 55.255688 | J139: 16.56668 | K139: 33.5164 | L139: 64.628753 | M139: 37.233246 | N139: 19.708114 | O139: 7.6680647 | P139: 42.219233 | Q139: 536.12576 | R139: 1114.7431 | S139: 917.85838 | T139: 1146.282 | AP139: 1.1360899 | AQ139: 0.74215955 | AU139: 0.85497068 | AV139: 0.25633607 | AW139: 0.51859889 | AX139: 0.88190247 | AY139: 0.46680417 | AZ139: 0.18162492
A140: CEF1207 (Driver) | B140: 2013 Dodge Dart | C140: car (sedan) | D140: Hybrid III | E140: 1622 | F140: 51.709259 | G140: 69.985018 | H140: 113515.7 | I140: 39.397695 | J140: 18.624168 | K140: 32.127758 | L140: 50.848212 | M140: 42.908496 | N140: 16.744284 | O140: 20.134766 | P140: 49.494184 | Q140: 494.31573 | R140: 142.04559 | S140: 1598.0306 | T140: 1642.6673 | AP140: 0.72655853 | AQ140: 0.70721114 | AU140: 0.77480984 | AV140: 0.36626988 | AW140: 0.63183655 | AX140: 0.86694016 | AY140: 0.33830812 | AZ140: 0.40681075
A141: CEF1208 (Driver) | B141: 2013 Nissan Altima | C141: car (sedan) | D141: Hybrid III | E141: 1552 | F141: 71.998462 | G141: 45.73213 | H141: 70976.266 | I141: 36.474084 | J141: 17.29534 | K141: 23.811583 | L141: 40.933779 | M141: 35.596646 | N141: 14.387532 | O141: 6.0955221 | P141: 38.46421 | Q141: 416.88183 | R141: 243.64784 | S141: 1023.9289 | T141: 1023.9934 | AP141: 0.89507702 | AQ141: 0.84107628 | AU141: 0.89105099 | AV141: 0.42252 | AW141: 0.58170988 | AX141: 0.9254485 | AY141: 0.37404984 | AZ141: 0.15847257
A142: CEF1301 (Driver) | B142: 2014 Mazda 6 | C142: car (sedan) | D142: Hybrid III | E142: 1570 | F142: 68.310752 | G142: 35.774498 | H142: 56165.961 | I142: 29.549761 | J142: 23.641306 | K142: 25.680867 | L142: 38.240803 | M142: 33.900921 | N142: 11.23655 | O142: 13.088312 | P142: 36.615107 | Q142: 544.88722 | R142: 466.34747 | S142: 1239.338 | T142: 1293.8368 | AP142: 1.0689403 | AQ142: 1.0234974 | AU142: 0.77272858 | AV142: 0.61822201 | AW142: 0.67155669 | AX142: 0.92587253 | AY142: 0.3068829 | AZ142: 0.35745661
A143: CEF1304 (Driver) | B143: 2014 Fiat 500 L | C143: car (hatchback) | D143: Hybrid III | E143: 1645 | F143: 61.891717 | G143: 47.672557 | H143: 78421.356 | I143: 55.517473 | J143: 33.500667 | K143: 29.162284 | L143: 66.845169 | M143: 38.549162 | N143: 16.912897 | O143: 20.371653 | P143: 44.412294 | Q143: 539.47772 | R143: 123.88195 | S143: 1946.6493 | T143: 1970.7001 | AP143: 1.4021729 | AQ143: 0.93161132 | AU143: 0.8305383 | AV143: 0.50116811 | AW143: 0.43626614 | AX143: 0.86798404 | AY143: 0.38081566 | AZ143: 0.45869402
A144: CEF1306 (Driver) | B144: 2013 Chevrolet Spark | C144: car (hatchback) | D144: Hybrid III | E144: 1195 | F144: 60.641519 | G144: 41.26106 | H144: 49306.966 | I144: 65.002913 | J144: 21.619651 | K144: 32.540222 | L144: 74.354774 | M144: 48.764259 | N144: 15.742458 | O144: 11.4405 | P144: 49.886476 | Q144: 784.46867 | R144: 195.93891 | S144: 1151.1896 | T144: 1180.6469 | AP144: 1.8020568 | AQ144: 1.209045 | AU144: 0.87422648 | AV144: 0.29076346 | AW144: 0.4376346 | AX144: 0.97750459 | AY144: 0.31556565 | AZ144: 0.22933069
A145: CEF1307 (Driver) | B145: 2014 Maserati Ghibli | C145: car (sedan) | D145: Hybrid III | E145: 2219 | F145: 70.203221 | G145: 43.656038 | H145: 96872.748 | I145: 55.103405 | J145: 9.069981 | K145: 36.794941 | L145: 59.714679 | M145: 31.960946 | N145: 9.4391453 | O145: 16.858712 | P145: 36.088374 | Q145: 585.05033 | R145: 368.03955 | S145: 679.22393 | T145: 781.96985 | AP145: 1.3678447 | AQ145: 0.82665254 | AU145: 0.92277823 | AV145: 0.15188863 | AW145: 0.61617917 | AX145: 0.88562997 | AY145: 0.2615564 | AZ145: 0.46715076
A146: CEF1308 (Driver) | B146: 2014 Mitsubishi Mirage | C146: car (hatchback) | D146: Hybrid III | E146: 1073 | F146: 67.401607 | G146: 49.907304 | H146: 53550.537 | I146: 44.812821 | J146: 38.11815 | K146: 34.209571 | L146: 52.539429 | M146: 42.014917 | N146: 11.254248 | O146: 17.907719 | P146: 44.13103 | Q146: 502.94637 | R146: 170.06028 | S146: 1799.8465 | T146: 1812.9109 | AP146: 1.0527403 | AQ146: 0.88425996 | AU146: 0.85293696 | AV146: 0.72551512 | AW146: 0.65112186 | AX146: 0.9520493 | AY146: 0.25501893 | AZ146: 0.40578519
A147: CEF1401 (Driver) | B147: 2014 BMW 2 Series | C147: car (sedan) | D147: Hybrid III | E147: 1622 | F147: 62.042228 | G147: 33.841987 | H147: 54891.702 | I147: 37.296006 | J147: 22.214114 | K147: 15.806209 | L147: 38.781849 | M147: 35.863772 | N147: 10.949485 | O147: 9.7573961 | P147: 37.535463 | Q147: 648.37779 | R147: 94.837996 | S147: 735.33389 | T147: 928.65095 | AP147: 1.1459685 | AQ147: 1.1091389 | AU147: 0.96168715 | AV147: 0.57279666 | AW147: 0.40756719 | AX147: 0.95546371 | AY147: 0.29171041 | AZ147: 0.2599514
A148: CEF1403 (Driver) | B148: 2015 Subaru WRX | C148: car (sedan) | D148: Hybrid III | E148: 1677 | F148: 63.656997 | G148: 41.843967 | H148: 70172.333 | I148: 70.114052 | J148: 22.561043 | K148: 45.495313 | L148: 80.252939 | M148: 49.312238 | N148: 27.229402 | O148: 11.041503 | P148: 51.830628 | Q148: 429.20347 | R148: 82.863988 | S148: 1825.9759 | T148: 1863.7047 | AP148: 1.9179094 | AQ148: 1.2386643 | AU148: 0.87366336 | AV148: 0.2811242 | AW148: 0.56689903 | AX148: 0.95141116 | AY148: 0.5253535 | AZ148: 0.21303047
...

Sheet SUV
A1: Test ID | B1: Vehicle Info | C1: Vehicle Type | D1: ATD | E1: Vehicle Test Weight (kg) | F1: Vehicle dV (kph) | G1: Vehicle Peak a (g) | H1: Vehicle Peak F (N) | I1: Driver Head Peak a - x (g) | J1: Driver Head Peak a - y (g) | K1: Driver Head Peak a - z (g) | L1: Driver Head Peak a - R (g) | M1: Driver Chest Peak a - x (g) | N1: Driver Chest Peak a - y (g) | O1: Driver Chest Peak a - z (g) | P1: Driver Chest Peak a - R (g) | Q1: Driver Upper Neck Peak F - x (N) | R1: Driver Upper Neck Peak F - z Compression (N) | S1: Driver Upper Neck Peak F - z Tension (N) | T1: Driver Upper Neck Peak F - R (N) | U1: Passenger Head Peak a - x (g) | V1: Passenger Head Peak a - y (g) | W1: Passenger Head Peak a - z (g) | X1: Passenger Head Peak a - R (g) | Y1: Passenger Chest Peak a - x (g) | Z1: Passenger Chest Peak a - y (g) | AA1: Passenger Chest Peak a - z (g) | AB1: Passenger Chest Peak a - R (g) | AC1: Passenger Pelvis Peak a - x (g) | AD1: Passenger Pelvis Peak a - y (g) | AE1: Passenger Pelvis Peak a - z (g) | AF1: Passenger Pelvis Peak a - R (g) | AG1: Passenger Upper Neck Peak F - x (N) | AH1: Passenger Upper Neck Peak F - z Compression (N) | AI1: Passenger Upper Neck Peak F - z Tension (N) | AJ1: Passenger Upper Neck Peak F - R (N) | AK1: Passenger Lumbar Peak F - x (N) | AL1: Passenger Lumbar Peak F - z Compression (N) | AM1: Passenger Lumbar Peak F - z Tension (N) | AN1: Passenger Lumbar Peak F - R (N) | AP1: Resultant Driver Head a / Vehicle Peak a | AQ1: Resultant Driver Chest a / Vehicle Peak a | AR1: Resultant Passenger Head a / Vehicle Peak a | AS1: Resultant Passenger Chest a / Vehicle Peak a | AT1: Resultant Passenger Pelvis a / Vehicle Peak a | AU1: Driver Head a x / Head a r | AV1: Driver Head a y / Head a r | AW1: Driver Head a z / Head a r | AX1: Driver Chest a x / Chest a r | AY1: Driver Chest a y / Chest a r | AZ1: Driver Chest a z / Chest a r | BA1: Passenger Head a x / Head a r | BB1: Passenger Head a y / Head a r | BC1: Passenger Head a z / Head a r | BD1: Passenger Chest a x / Chest a r | BE1: Passenger Chest a y / Chest a r | BF1: Passenger Chest a z / Chest a r | BG1: Passenger Pelvis a x / Pelvis a r | BH1: Passenger Pelvis a y / Pelvis a r | BI1: Passenger Pelvis a z / Pelvis a r
A2: CEF0104 | B2: 2001 Hyundai Santa Fe | C2: SUV | D2: Hybrid III | E2: 1845 | F2: 69.7109 | G2: 41.2371 | H2: 76082.45 | I2: 99.5381 | J2: 14.5851 | K2: 46.3536 | L2: 110.2865 | M2: 56.9783 | N2: 26.2963 | O2: 12.6761 | P2: 59.4511 | Q2: 489.7462 | R2: 946.6205 | S2: 1621.7365 | T2: 1657.0736 | AP2: 2.6744485 | AQ2: 1.4416896 | AU2: 0.90254111 | AV2: 0.13224737 | AW2: 0.42030167 | AX2: 0.95840615 | AY2: 0.44231814 | AZ2: 0.21321893
A3: CEF0105 | B3: 2001 Ford Escape | C3: SUV | D3: Hybrid III | E3: 1652 | F3: 68.3126 | G3: 82.2404 | H3: 135861.14 | I3: 84.9355 | J3: 23.2934 | K3: 31.5172 | L3: 89.1041 | M3: 41.6622 | N3: 17.7547 | O3: 12.2229 | P3: 44.5618 | Q3: 631.357 | R3: 755.6129 | S3: 2266.3536 | T3: 2351.3926 | AP3: 1.083459 | AQ3: 0.54184805 | AU3: 0.95321652 | AV3: 0.26141782 | AW3: 0.35371212 | AX3: 0.93493082 | AY3: 0.3984287 | AZ3: 0.27429098
A4: CEF0106 | B4: 2001 Toyota RAV4 | C4: SUV | D4: Hybrid III | E4: 1512 | F4: 69.8689 | G4: 46.6231 | H4: 70494.127 | I4: 72.731 | J4: 17.7613 | K4: 30.9637 | L4: 72.8052 | M4: 55.9396 | N4: 21.5802 | O4: 23.1638 | P4: 58.3902 | Q4: 507.4753 | R4: 351.839 | S4: 1892.3941 | T4: 1894.5918 | AP4: 1.5615693 | AQ4: 1.2523878 | AU4: 0.99898084 | AV4: 0.24395648 | AW4: 0.42529517 | AX4: 0.95803063 | AY4: 0.36958599 | AZ4: 0.39670698
A5: CEF0113 | B5: 2001 Acura MDX | C5: SUV | D5: Hybrid III | E5: 2095 | F5: 70.703043 | G5: 44.043304 | H5: 92270.722 | I5: 53.01927 | J5: 12.244222 | K5: 11.826501 | L5: 53.802754 | M5: 41.105712 | N5: 17.842732 | O5: 9.85584 | P5: 44.292955 | Q5: 530.33682 | R5: 174.11759 | S5: 1254.1299 | T5: 1254.4323 | AP5: 1.2215876 | AQ5: 1.0056683 | AU5: 0.98543785 | AV5: 0.22757612 | AW5: 0.21981219 | AX5: 0.92804176 | AY5: 0.40283454 | AZ5: 0.22251484
A6: CEF0114 | B6: 2001 Pontiac Aztek | C6: SUV | D6: Hybrid III | E6: 1963 | F6: 72.253291 | G6: 31.017468 | H6: 60887.29 | I6: 96.411408 | J6: 28.837521 | K6: 23.143857 | L6: 97.55269 | M6: 43.839994 | N6: 9.778939 | O6: 17.004198 | P6: 45.736222 | Q6: 366.91648 | R6: 124.82187 | S6: 1908.7567 | T6: 1915.4611 | AP6: 3.1450888 | AQ6: 1.4745311 | AU6: 0.98830087 | AV6: 0.2956097 | AW6: 0.23724468 | AX6: 0.95853991 | AY6: 0.21381169 | AZ6: 0.37178843
A7: CEF0115 | B7: 2001 Mitsubishi Montero Sport | C7: SUV | D7: Hybrid III | E7: 2022 | F7: 68.689885 | G7: 57.181531 | H7: 115621.06 | I7: 60.94832 | J7: 22.677742 | K7: 17.452039 | L7: 61.570664 | M7: 52.980715 | N7: 21.448929 | O7: 10.941457 | P7: 57.663184 | Q7: 356.89953 | R7: 957.87719 | S7: 1823.9503 | T7: 1825.5335 | AP7: 1.0767579 | AQ7: 1.0084232 | AU7: 0.9898922 | AV7: 0.36832057 | AW7: 0.28344731 | AX7: 0.91879621 | AY7: 0.37196921 | AZ7: 0.18974771
A8: CEF0116 | B8: 2001 Suzuki XL-7 | C8: SUV | D8: Hybrid III | E8: 1771 | F8: 71.777684 | G8: 36.887736 | H8: 65328.18 | I8: 50.885017 | J8: 17.738286 | K8: 34.907912 | L8: 54.913204 | M8: 41.556104 | N8: 16.289453 | O8: 15.206706 | P8: 44.55949 | Q8: 674.79147 | R8: 1041.4606 | S8: 2440.2029 | T8: 2531.2782 | AP8: 1.4886575 | AQ8: 1.2079757 | AU8: 0.92664447 | AV8: 0.32302406 | AW8: 0.6356925 | AX8: 0.93259829 | AY8: 0.36556641 | AZ8: 0.34126751
A9: CEF0117 | B9: 2001 Toyota Highlander | C9: SUV | D9: Hybrid III | E9: 1864 | F9: 69.9655 | G9: 58.598444 | H9: 109227.5 | I9: 82.653827 | J9: 22.809464 | K9: 29.757736 | L9: 82.707599 | M9: 44.531203 | N9: 19.11361 | O9: 19.948493 | P9: 47.245958 | Q9: 430.02867 | R9: 399.23945 | S9: 1691.2144 | T9: 1694.1126 | AP9: 1.41143 | AQ9: 0.80626643 | AU9: 0.99934985 | AV9: 0.27578438 | AW9: 0.35979446 | AX9: 0.94253995 | AY9: 0.40455545 | AZ9: 0.42222645
A10: CEF0118 | B10: 2002 Isuzu Axiom | C10: SUV | D10: Hybrid III | E10: 1990 | F10: 69.055933 | G10: 46.405013 | H10: 92345.976 | I10: 69.292231 | J10: 22.137641 | K10: 18.246116 | L10: 73.73486 | M10: 55.093844 | N10: 15.956265 | O10: 14.873672 | P10: 55.456287 | Q10: 533.69528 | R10: 260.20815 | S10: 1923.1975 | T10: 1956.8787 | AP10: 1.5889417 | AQ10: 1.1950495 | AU10: 0.93974859 | AV10: 0.30023304 | AW10: 0.24745576 | AX10: 0.99346435 | AY10: 0.28772689 | AZ10: 0.26820533
A11: CEF0119 | B11: 2002 Chevrolet Trailblazer | C11: SUV | D11: Hybrid III | E11: 2179 | F11: 67.137097 | G11: 36.528723 | H11: 79596.087 | I11: 184.15168 | J11: 58.632131 | K11: 67.979829 | L11: 204.35992 | M11: 52.497162 | N11: 10.405632 | O11: 13.02543 | P11: 53.320089 | Q11: 636.94798 | R11: 1112.5595 | S11: 1913.0824 | T11: 1952.0096 | AP11: 5.5944994 | AQ11: 1.4596757 | AU11: 0.90111448 | AV11: 0.28690622 | AW11: 0.33264756 | AX11: 0.98456629 | AY11: 0.19515406 | AZ11: 0.24428748
A12: CEF0120 | B12: 2002 Buick Rendezvous | C12: SUV | D12: Hybrid III | E12: 2008 | F12: 72.044643 | G12: 37.472629 | H12: 75245.039 | I12: 49.825205 | J12: 5.345132 | K12: 13.949648 | L12: 51.713296 | M12: 44.04493 | N12: 6.675281 | O12: 14.960561 | P12: 45.187929 | Q12: 326.69922 | R12: 303.34185 | S12: 1611.3061 | T12: 1620.4577 | AP12: 1.3800285 | AQ12: 1.2058916 | AU12: 0.96348925 | AV12: 0.10336088 | AW12: 0.26974974 | AX12: 0.97470566 | AY12: 0.14772266 | AZ12: 0.33107428
A13: CEF0121 | B13: 2002 Isuzu Rodeo | C13: SUV | D13: Hybrid III | E13: 1956 | F13: 70.468031 | G13: 55.208341 | H13: 107987.51 | I13: 79.547199 | J13: 14.489012 | K13: 12.465619 | L13: 80.378593 | M13: 50.51813 | N13: 12.910093 | O13: 15.837939 | P13: 52.170038 | Q13: 598.50139 | R13: 1382.1 | S13: 2403.9266 | T13: 2408.5753 | AP13: 1.4559139 | AQ13: 0.94496659 | AU13: 0.98965652 | AV13: 0.18025959 | AW13: 0.15508631 | AX13: 0.96833608 | AY13: 0.24746183 | AZ13: 0.30358305
... A40: CEF0718 | B40: 2007 Nissan Pathfinder | C40: SUV | D40: Hybrid III | E40: 2228 | F40: 68.040957 | G40: 47.307763 | H40: 105401.7 | I40: 50.689877 | J40: 17.521745 | K40: 34.51129 | L40: 60.623249 | M40: 39.268497 | N40: 13.674809 | O40: 11.344434 | P40: 41.697171 | Q40: 701.08795 | R40: 60.606029 | S40: 1396.6276 | T40: 1522.3406 | AP40: 1.2814651 | AQ40: 0.8814023 | AU40: 0.83614583 | AV40: 0.28902682 | AW40: 0.56927483 | AX40: 0.94175447 | AY40: 0.32795532 | AZ40: 0.27206723
A41: CEF0719 | B41: 2007 Chevrolet TrailBlazer | C41: SUV | D41: Hybrid III | E41: 2206 | F41: 70.508377 | G41: 39.215088 | I41: 59.833402 | J41: 10.057422 | K41: 31.198716 | L41: 66.813247 | M41: 47.447152 | N41: 13.821807 | O41: 12.705497 | P41: 48.500226 | Q41: 472.93958 | R41: 371.53953 | S41: 1418.3995 | T41: 1424.4771 | AP41: 1.7037638 | AQ41: 1.2367746 | AU41: 0.89553202 | AV41: 0.15053036 | AW41: 0.46695405 | AX41: 0.97828724 | AY41: 0.28498438 | AZ41: 0.26196779
A42: CEF0720 | B42: 2007 Jeep Grand Cherokee | C42: SUV | D42: Hybrid III | E42: 2160 | F42: 71.186615 | G42: 45.990998 | H42: 99340.556 | I42: 51.094114 | J42: 38.902158 | K42: 30.862794 | L42: 53.449601 | M42: 40.73922 | N42: 12.18675 | O42: 13.79896 | P42: 40.957019 | Q42: 440.97019 | R42: 2740.4889 | S42: 1629.9209 | T42: 2772.5694 | AP42: 1.1621753 | AQ42: 0.89054425 | AU42: 0.95593069 | AV42: 0.72782878 | AW42: 0.5774186 | AX42: 0.99468225 | AY42: 0.29754973 | AZ42: 0.33691319
A43: CEF0722 | B43: 2008 BMW X3 | C43: SUV | D43: Hybrid III | E43: 1940 | F43: 69.594373 | G43: 38.34478 | H43: 74388.873 | I43: 67.607887 | J43: 18.523001 | K43: 26.140204 | L43: 72.638722 | M43: 46.60995 | N43: 16.575007 | O43: 12.057484 | P43: 48.05531 | Q43: 965.00591 | R43: 135.62088 | S43: 1187.047 | T43: 1388.5549 | AP43: 1.8943575 | AQ43: 1.2532426 | AU43: 0.93074169 | AV43: 0.25500175 | AW43: 0.35986597 | AX43: 0.96992299 | AY43: 0.3449152 | AZ43: 0.25090846
A44: CEF0723 | B44: 2008 Jeep Wrangler | C44: SUV | D44: Hybrid III | E44: 2083 | F44: 69.793529 | G44: 25.645811 | H44: 53420.224 | I44: 43.334693 | J44: 9.099427 | K44: 21.984091 | L44: 45.112786 | M44: 39.576769 | N44: 15.911079 | O44: 8.547013 | P44: 40.358507 | Q44: 520.70387 | R44: 148.45553 | S44: 1048.7844 | T44: 1105.1374 | AP44: 1.7590704 | AQ44: 1.5736881 | AU44: 0.96058561 | AV44: 0.20170395 | AW44: 0.48731397 | AX44: 0.98063016 | AY44: 0.3942435 | AZ44: 0.21177723
A45: CEF0724 | B45: 2008 Jeep Liberty | C45: SUV | D45: Hybrid III | E45: 2065 | F45: 70.503936 | G45: 39.684596 | H45: 81948.691 | I45: 50.868435 | J45: 7.779426 | K45: 21.49134 | L45: 54.375739 | M45: 44.742466 | N45: 6.743019 | O45: 8.868053 | P45: 44.834396 | Q45: 972.0935 | R45: 754.91664 | S45: 1066.2517 | T45: 1207.6009 | AP45: 1.3701976 | AQ45: 1.1297682 | AU45: 0.93549873 | AV45: 0.14306796 | AW45: 0.39523766 | AX45: 0.99794957 | AY45: 0.15039835 | AZ45: 0.19779575
A46: CEF0725 | B46: 2008 Mazda CX-7 | C46: SUV | D46: Hybrid III | E46: 1885 | F46: 69.813106 | G46: 35.154612 | H46: 66266.444 | I46: 82.875556 | J46: 29.603473 | K46: 26.416947 | L46: 85.640399 | M46: 60.828977 | N46: 17.892196 | O46: 20.785104 | P46: 65.693515 | Q46: 706.20415 | R46: 952.95352 | S46: 1332.5571 | T46: 1403.5571 | AP46: 2.4361071 | AQ46: 1.8687026 | AU46: 0.96771567 | AV46: 0.34567182 | AW46: 0.30846361 | AX46: 0.92595102 | AY46: 0.27235863 | AZ46: 0.31639507
A47: CEF0726 | B47: 2008 Infiniti EX35 | C47: SUV | D47: Hybrid III | E47: 1896 | F47: 66.846624 | G47: 54.894964 | H47: 104080.85 | I47: 49.73426 | J47: 18.344133 | K47: 25.631872 | L47: 51.784358 | M47: 43.338642 | N47: 16.808112 | O47: 13.476265 | P47: 44.962258 | Q47: 547.36507 | R47: 1435.1299 | S47: 1073.2716 | T47: 1463.6017 | AP47: 0.94333531 | AQ47: 0.8190598 | AU47: 0.96041086 | AV47: 0.35424081 | AW47: 0.49497325 | AX47: 0.96388936 | AY47: 0.37382713 | AZ47: 0.29972394
A48: CEF0727 | B48: 2008 Kia Sorento | C48: SUV | D48: Hybrid III | E48: 2067 | F48: 70.342964 | G48: 48.756852 | H48: 100780.41 | I48: 53.636922 | J48: 15.142576 | K48: 39.074686 | L48: 65.34297 | M48: 37.777118 | N48: 16.524885 | O48: 23.031589 | P48: 42.838057 | Q48: 674.54646 | R48: 80.093031 | S48: 1771.0837 | T48: 1862.1377 | AP48: 1.3401802 | AQ48: 0.87860588 | AU48: 0.82085222 | AV48: 0.23173994 | AW48: 0.59799372 | AX48: 0.88185881 | AY48: 0.38575244 | AZ48: 0.53764318
A49: CEF0801 | B49: 2008 Hummer H3 | C49: SUV | D49: Hybrid III | E49: 2317 | F49: 71.170444 | G49: 38.969272 | H49: 90291.803 | I49: 61.715779 | J49: 12.889921 | K49: 25.596321 | L49: 65.733079 | M49: 45.594143 | N49: 18.309692 | O49: 17.291933 | P49: 51.053092 | Q49: 396.59571 | R49: 94.887607 | S49: 1931.5045 | T49: 1948.126 | AP49: 1.6867926 | AQ49: 1.3100859 | AU49: 0.93888465 | AV49: 0.19609489 | AW49: 0.38939787 | AX49: 0.8930731 | AY49: 0.35864022 | AZ49: 0.33870491
A50: CEF0802 | B50: 2008 Mazda CX-9 | C50: SUV | D50: Hybrid III | E50: 2192 | F50: 69.930379 | G50: 37.730713 | H50: 82705.723 | I50: 89.189406 | J50: 40.645794 | K50: 36.487054 | L50: 98.30844 | M50: 47.225125 | N50: 31.883368 | O50: 27.87648 | P50: 58.365902 | Q50: 2081.2507 | R50: 1144.6995 | S50: 1538.1837 | T50: 2230.6186 | AP50: 2.6055283 | AQ50: 1.5469069 | AU50: 0.90724058 | AV50: 0.41345172 | AW50: 0.37114874 | AX50: 0.80912182 | AY50: 0.54626703 | AZ50: 0.47761585
A51: CEF0808 | B51: 2008 Jeep Patriot | C51: SUV | D51: Hybrid III | E51: 1656 | F51: 70.092733 | G51: 58.653197 | H51: 97129.695 | I51: 73.050511 | J51: 21.751818 | K51: 29.01193 | L51: 78.378944 | M51: 47.345498 | N51: 17.365394 | O51: 17.559057 | P51: 50.391783 | Q51: 658.31406 | R51: 2164.2 | S51: 1483.0679 | T51: 2247.6662 | AP51: 1.3363115 | AQ51: 0.8591481 | AU51: 0.93201703 | AV51: 0.27752119 | AW51: 0.37014954 | AX51: 0.93954798 | AY51: 0.34460766 | AZ51: 0.3484508
A52: CEF0810 | B52: 2008 Suzuki Grand Vitara | C52: SUV | D52: Hybrid III | E52: 1791 | F52: 67.478063 | G52: 45.338842 | H52: 81201.866 | I52: 61.887231 | J52: 10.34211 | K52: 32.284707 | L52: 70.092101 | M52: 52.727912 | N52: 20.27167 | O52: 8.205735 | P52: 55.577467 | Q52: 1045.6803 | R52: 356.11656 | S52: 1352.7102 | T52: 1396.9026 | AP52: 1.5459614 | AQ52: 1.2258246 | AU52: 0.88294159 | AV52: 0.14755029 | AW52: 0.46060407 | AX52: 0.94872824 | AY52: 0.36474621 | AZ52: 0.147645
A53: CEF0812 | B53: 2008 Nissan Rogue | C53: SUV | D53: Hybrid III | E53: 1668 | F53: 72.307012 | G53: 42.231462 | H53: 70442.079 | I53: 72.95632 | J53: 14.799766 | K53: 29.574269 | L53: 73.357265 | M53: 42.159393 | N53: 16.650851 | O53: 12.373135 | P53: 45.013517 | Q53: 953.56047 | R53: 218.15581 | S53: 1348.0373 | T53: 1358.3073 | AP53: 1.7370288 | AQ53: 1.0658763 | AU53: 0.99453434 | AV53: 0.20174916 | AW53: 0.40315392 | AX53: 0.93659408 | AY53: 0.3699078 | AZ53: 0.27487598
... A66: CEF1206 (Driver) | B66: 2013 Ford Escape | C66: SUV | D66: Hybrid III | E66: 1791 | F66: 69.638934 | G66: 36.98994 | H66: 66248.982 | I66: 47.918619 | J66: 20.494719 | K66: 23.660537 | L66: 54.883727 | M66: 30.199087 | N66: 11.781684 | O66: 17.097448 | P66: 35.614543 | Q66: 961.20225 | R66: 263.60489 | S66: 1097.1662 | T66: 1430.4573 | AP66: 1.4837474 | AQ66: 0.96281701 | AU66: 0.87309339 | AV66: 0.3734207 | AW66: 0.43110296 | AX66: 0.84794255 | AY66: 0.33081104 | AZ66: 0.48006926
A67: CEF1302 (Driver) | B67: 2013 BMW X1 | C67: SUV | D67: Hybrid III | E67: 1845 | F67: 69.787627 | G67: 57.211433 | I67: 47.947416 | J67: 22.254158 | K67: 21.384197 | L67: 53.709993 | M67: 43.969269 | N67: 15.984555 | O67: 12.640705 | P67: 48.241899 | Q67: 1102.9602 | R67: 173.05851 | S67: 926.62757 | T67: 1423.5156 | AP67: 0.93879824 | AQ67: 0.84322131 | AU67: 0.89270942 | AV67: 0.41433926 | AW67: 0.39814187 | AX67: 0.91143321 | AY67: 0.33134175 | AZ67: 0.26202752
A68: CEF1303 (Driver) | B68: 2013 Buick Encore | C68: SUV | D68: Hybrid III | E68: 1643 | F68: 69.090308 | G68: 43.746588 | H68: 71875.644 | I68: 34.180433 | J68: 26.106318 | K68: 26.458321 | L68: 45.289298 | M68: 34.296716 | N68: 12.138071 | O68: 19.47606 | P68: 37.173147 | Q68: 709.9093 | R68: 146.64654 | S68: 1192.3788 | T68: 1307.2299 | AP68: 1.0352647 | AQ68: 0.84973822 | AU68: 0.75471325 | AV68: 0.57643461 | AW68: 0.58420692 | AX68: 0.92262071 | AY68: 0.32652794 | AZ68: 0.52392818
A69: CEF1305 (Driver) | B69: 2014 Jeep Cherokee | C69: SUV | D69: Hybrid III | E69: 1933 | F69: 61.759759 | G69: 41.180229 | H69: 79601.383 | I69: 44.980805 | J69: 20.210483 | K69: 17.793911 | L69: 48.387852 | M69: 38.767968 | N69: 22.927189 | O69: 23.973795 | P69: 48.307182 | Q69: 554.50116 | R69: 26.054731 | S69: 1604.6049 | T69: 1687.1394 | AP69: 1.1750263 | AQ69: 1.1730674 | AU69: 0.92958879 | AV69: 0.4176768 | AW69: 0.36773509 | AX69: 0.8025301 | AY69: 0.47461242 | AZ69: 0.49627806
A70: CEF1402 (Driver) | B70: 2014 Nissan Rogue | C70: SUV | D70: Hybrid III | E70: 1720 | F70: 62.567084 | G70: 34.554341 | H70: 59433.467 | I70: 55.798316 | J70: 11.160382 | K70: 25.906475 | L70: 61.305316 | M70: 37.090669 | N70: 9.6297062 | O70: 6.8794546 | P70: 38.732323 | Q70: 590.7755 | R70: 121.89171 | S70: 1013.4161 | T70: 1029.9474 | AP70: 1.7741712 | AQ70: 1.1209105 | AU70: 0.91017093 | AV70: 0.18204591 | AW70: 0.42258122 | AX70: 0.95761539 | AY70: 0.24862196 | AZ70: 0.17761534
A71: CEF1501 (Driver) | B71: 2016 Audi Q3 | C71: SUV | D71: Hybrid III | E71: 1777 | F71: 67.20294 | G71: 42.839185 | H71: 76125.232 | I71: 45.898895 | J71: 19.287988 | K71: 31.649574 | L71: 49.13132 | M71: 38.47655 | N71: 16.417534 | O71: 12.830693 | P71: 41.836696 | Q71: 369.86157 | R71: 195.01219 | S71: 1223.2897 | T71: 1224.1652 | AP71: 1.146878 | AQ71: 0.97659878 | AU71: 0.93420847 | AV71: 0.39258029 | AW71: 0.64418326 | AX71: 0.91968423 | AY71: 0.39241947 | AZ71: 0.30668513
A72: CEF1504 (Driver) | B72: 2015 Jeep Renegade | C72: SUV | D72: Hybrid III | E72: 1657 | F72: 69.096231 | G72: 49.242288 | H72: 81594.471 | I72: 59.644031 | J72: 6.169876 | K72: 39.222626 | L72: 68.023179 | M72: 41.059488 | N72: 7.0299606 | O72: 22.133699 | P72: 42.921286 | Q72: 922.60593 | R72: 81.174626 | S72: 1572.6013 | T72: 1637.4216 | AP72: 1.3813976 | AQ72: 0.87163467 | AU72: 0.87681922 | AV72: 0.090702552 | AW72: 0.57660678 | AX72: 0.95662298 | AY72: 0.16378728 | AZ72: 0.51568119
A73: CEF1605 (Driver) | B73: 2016 BMW X1 | C73: SUV | D73: Hybrid III | E73: 1834 | F73: 67.139267 | G73: 44.004018 | H73: 80703.369 | I73: 34.426545 | J73: 31.875422 | K73: 33.053702 | L73: 50.339303 | M73: 39.86702 | N73: 18.200589 | O73: 17.934905 | P73: 42.568718 | Q73: 382.34091 | R73: 103.9267 | S73: 1560.8069 | T73: 1605.7519 | AP73: 1.1439706 | AQ73: 0.96738253 | AU73: 0.68388999 | AV73: 0.63321142 | AW73: 0.6566182 | AX73: 0.93653324 | AY73: 0.42755783 | AZ73: 0.42131654
A74: CEF1608 (Driver) | B74: 2016 Mazda CX-3 | C74: SUV | D74: Hybrid III | E74: 1443 | F74: 67.386815 | G74: 41.359576 | H74: 59681.868 | I74: 38.190954 | J74: 23.638426 | K74: 30.772258 | L74: 50.929105 | M74: 37.968957 | N74: 17.077765 | O74: 16.264173 | P74: 41.522728 | Q74: 475.97054 | R74: 203.59817 | S74: 1497.1824 | T74: 1528.9856 | AP74: 1.231374 | AQ74: 1.0039447 | AU74: 0.74988464 | AV74: 0.46414375 | AW74: 0.60421753 | AX74: 0.91441384 | AY74: 0.41128716 | AZ74: 0.39169327
A75: CEF1609 (Driver) | B75: 2016 Buick Envision | C75: SUV | D75: Hybrid III | E75: 1965 | F75: 69.093428 | G75: 37.245527 | H75: 73187.461 | I75: 37.492927 | J75: 28.079841 | K75: 23.894452 | L75: 43.959878 | M75: 39.032768 | N75: 19.213367 | O75: 11.917238 | P75: 43.15529 | Q75: 757.18389 | R75: 111.63618 | S75: 1575.7043 | T75: 1748.1909 | AP75: 1.1802727 | AQ75: 1.1586704 | AU75: 0.85288969 | AV75: 0.63876067 | AW75: 0.54355137 | AX75: 0.90447238 | AY75: 0.44521465 | AZ75: 0.27614778
A76: CEF1702 (Driver) | B76: 2017 Honda CR-V | C76: SUV | D76: Hybrid III | E76: 1693 | F76: 72.568554 | G76: 61.326153 | H76: 103825.18 | I76: 39.036177 | J76: 29.868991 | K76: 27.833452 | L76: 48.956552 | M76: 38.783672 | N76: 16.340653 | O76: 14.490765 | P76: 43.746891 | Q76: 449.32228 | R76: 120.20399 | S76: 1165.69 | T76: 1182.6295 | AP76: 0.79829812 | AQ76: 0.71334804 | AU76: 0.79736369 | AV76: 0.61011222 | AW76: 0.56853374 | AX76: 0.88654694 | AY76: 0.37352719 | AZ76: 0.33124103
A77: CEF1801 | B77: 2018 Hyundai Kona | C77: SUV | D77: Hybrid III | E77: 1524 | F77: 70.323297 | G77: 43.98069 | H77: 67026.571 | I77: 42.834831 | J77: 24.79732 | K77: 36.33457 | L77: 55.46766 | M77: 42.480175 | N77: 14.481617 | O77: 8.464516 | P77: 44.416525 | Q77: 616.96991 | R77: 284.04151 | S77: 1171.7614 | T77: 1251.3332 | AP77: 1.2611821 | AQ77: 1.0099097 | AU77: 0.77224876 | AV77: 0.44705906 | AW77: 0.65505864 | AX77: 0.95640474 | AY77: 0.3260412 | AZ77: 0.19057132
A78: CEF1802 | B78: 2019 Subaru Ascent | C78: SUV | D78: Hybrid III | E78: 2097 | F78: 71.277299 | G78: 40.796479 | H78: 85550.216 | I78: 34.904197 | J78: 14.891668 | K78: 30.429296 | L78: 47.108716 | M78: 40.046046 | N78: 15.000944 | O78: 13.033487 | P78: 42.935815 | Q78: 570.43451 | R78: 97.184465 | S78: 1263.9651 | T78: 1271.3437 | AP78: 1.154725 | AQ78: 1.0524392 | AU78: 0.74092864 | AV78: 0.31611281 | AW78: 0.64593771 | AX78: 0.9326956 | AY78: 0.34938068 | AZ78: 0.30355746
...

Sheet Minivan
A1: Test ID | B1: Vehicle Info | C1: Vehicle Type | D1: ATD | E1: Vehicle Test Weight (kg) | F1: Vehicle dV (kph) | G1: Vehicle Peak a (g) | H1: Vehicle Peak F (N) | I1: Driver Head Peak a - x (g) | J1: Driver Head Peak a - y (g) | K1: Driver Head Peak a - z (g) | L1: Driver Head Peak a - R (g) | M1: Driver Chest Peak a - x (g) | N1: Driver Chest Peak a - y (g) | O1: Driver Chest Peak a - z (g) | P1: Driver Chest Peak a - R (g) | Q1: Driver Upper Neck Peak F - x (N) | R1: Driver Upper Neck Peak F - z Compression (N) | S1: Driver Upper Neck Peak F - z Tension (N) | T1: Driver Upper Neck Peak F - R (N) | U1: Passenger Head Peak a - x (g) | V1: Passenger Head Peak a - y (g) | W1: Passenger Head Peak a - z (g) | X1: Passenger Head Peak a - R (g) | Y1: Passenger Chest Peak a - x (g) | Z1: Passenger Chest Peak a - y (g) | AA1: Passenger Chest Peak a - z (g) | AB1: Passenger Chest Peak a - R (g) | AC1: Passenger Pelvis Peak a - x (g) | AD1: Passenger Pelvis Peak a - y (g) | AE1: Passenger Pelvis Peak a - z (g) | AF1: Passenger Pelvis Peak a - R (g) | AG1: Passenger Upper Neck Peak F - x (N) | AH1: Passenger Upper Neck Peak F - z Compression (N) | AI1: Passenger Upper Neck Peak F - z Tension (N) | AJ1: Passenger Upper Neck Peak F - R (N) | AK1: Passenger Lumbar Peak F - x (N) | AL1: Passenger Lumbar Peak F - z Compression (N) | AM1: Passenger Lumbar Peak F - z Tension (N) | AN1: Passenger Lumbar Peak F - R (N) | AP1: Resultant Driver Head a / Vehicle Peak a | AQ1: Resultant Driver Chest a / Vehicle Peak a | AR1: Resultant Passenger Head a / Vehicle Peak a | AS1: Resultant Passenger Chest a / Vehicle Peak a | AT1: Resultant Passenger Pelvis a / Vehicle Peak a | AU1: Driver Head a x / Head a r | AV1: Driver Head a y / Head a r | AW1: Driver Head a z / Head a r | AX1: Driver Chest a x / Chest a r | AY1: Driver Chest a y / Chest a r | AZ1: Driver Chest a z / Chest a r | BA1: Passenger Head a x / Head a r | BB1: Passenger Head a y / Head a r | BC1: Passenger Head a z / Head a r | BD1: Passenger Chest a x / Chest a r | BE1: Passenger Chest a y / Chest a r | BF1: Passenger Chest a z / Chest a r | BG1: Passenger Pelvis a x / Pelvis a r | BH1: Passenger Pelvis a y / Pelvis a r | BI1: Passenger Pelvis a z / Pelvis a r
A2: CEF0102 | B2: 2001 Dodge Grand Caravan | C2: minivan | D2: Hybrid III | E2: 2025 | F2: 70.9955 | G2: 37.1244 | H2: 75176.91 | I2: 76.3604 | J2: 13.8222 | K2: 27.2239 | L2: 81.1397 | M2: 45.5134 | N2: 14.3403 | O2: 13.388 | P2: 48.5693 | Q2: 472.8352 | R2: 954.1116 | S2: 2002.4788 | T2: 2029.0835 | AP2: 2.1856165 | AQ2: 1.3082851 | AU2: 0.94109788 | AV2: 0.17035064 | AW2: 0.33551886 | AX2: 0.93708165 | AY2: 0.29525441 | AZ2: 0.27564737
A3: CEF0111 | B3: 2001 Dodge Grand Caravan | C3: minivan | D3: Hybrid III | E3: 2040 | F3: 67.7742 | G3: 36.3315 | H3: 74116.26 | I3: 62.3191 | J3: 11.5395 | K3: 29.9674 | L3: 69.5415 | M3: 44.6362 | N3: 18.0332 | O3: 9.9215 | P3: 47.7105 | Q3: 600.7932 | R3: 29.3558 | S3: 1941.0255 | T3: 1983.1781 | AP3: 1.9140828 | AQ3: 1.3131993 | AU3: 0.89614259 | AV3: 0.16593689 | AW3: 0.43092829 | AX3: 0.93556345 | AY3: 0.37797131 | AZ3: 0.20795213
A4: CEF0201 | B4: 2002 Kia Sedona | C4: minivan | D4: Hybrid III | E4: 2216 | F4: 71.217144 | G4: 30.291491 | H4: 67125.944 | I4: 87.306184 | J4: 29.5889 | K4: 25.399609 | L4: 93.710934 | M4: 42.826319 | N4: 15.547339 | O4: 15.946153 | P4: 46.778932 | Q4: 606.53304 | R4: 158.38488 | S4: 2525.9053 | T4: 2555.6017 | AP4: 3.0936389 | AQ4: 1.5442928 | AU4: 0.93165419 | AV4: 0.31574651 | AW4: 0.27104211 | AX4: 0.91550442 | AY4: 0.33235772 | AZ4: 0.34088322
A5: CEF0310 | B5: 2004 Toyota Sienna | C5: minivan | D5: Hybrid III | E5: 2010 | F5: 69.502419 | G5: 35.270304 | H5: 70893.311 | I5: 38.012837 | J5: 22.347405 | K5: 18.028472 | L5: 38.19097 | M5: 45.895344 | N5: 19.441641 | O5: 9.209947 | P5: 48.581339 | Q5: 306.9259 | R5: 41.833124 | S5: 1422.7805 | T5: 1422.9117 | AP5: 1.0828081 | AQ5: 1.3774006 | AU5: 0.99533573 | AV5: 0.58514892 | AW5: 0.47206112 | AX5: 0.94471138 | AY5: 0.40018743 | AZ5: 0.18957787
A6: CEF0314 | B6: 2004 Toyota Sienna | C6: minivan | D6: Hybrid III | E6: 2014 | F6: 70.359947 | G6: 38.042565 | H6: 76617.726 | I6: 37.430151 | J6: 23.094274 | K6: 20.023652 | L6: 40.562846 | M6: 48.055655 | N6: 22.167525 | O6: 9.594622 | P6: 52.776651 | Q6: 349.38732 | R6: 30.143275 | S6: 1275.986 | T6: 1282.9401 | AP6: 1.066249 | AQ6: 1.3873053 | AU6: 0.92276935 | AV6: 0.5693455 | AW6: 0.49364515 | AX6: 0.91054764 | AY6: 0.42002523 | AZ6: 0.18179672
A7: CEF0317 | B7: 2004 Nissan Quest | C7: minivan | D7: Hybrid III | E7: 2026 | F7: 71.38133 | G7: 45.811892 | H7: 92814.893 | I7: 67.66776 | J7: 18.624181 | K7: 27.459163 | L7: 71.765437 | M7: 49.500664 | N7: 17.827558 | O7: 11.124913 | P7: 50.969419 | Q7: 552.03047 | R7: 225.74547 | S7: 1989.0722 | T7: 2003.4585 | AP7: 1.5665242 | AQ7: 1.1125805 | AU7: 0.9429018 | AV7: 0.25951463 | AW7: 0.38262378 | AX7: 0.9711836 | AY7: 0.34976969 | AZ7: 0.21826643
A8: CEF0327 | B8: 2004 Ford Freestar | C8: minivan | D8: Hybrid III | E8: 2056 | F8: 71.451756 | G8: 38.629672 | H8: 79422.606 | I8: 78.0467 | J8: 30.366162 | K8: 25.001231 | L8: 85.625712 | M8: 40.253551 | N8: 15.71831 | O8: 15.354677 | P8: 42.700009 | Q8: 514.26245 | R8: 238.74677 | S8: 1401.8921 | T8: 1402.9144 | AP8: 2.2165788 | AQ8: 1.1053681 | AU8: 0.91148673 | AV8: 0.35463836 | AW8: 0.29198275 | AX8: 0.94270591 | AY8: 0.36811023 | AZ8: 0.35959423
A9: CEF0508 | B9: 2005 Chevrolet Uplander | C9: minivan | D9: Hybrid III | E9: 2028 | F9: 76.075043 | G9: 35.726526 | H9: 72453.395 | I9: 133.95677 | J9: 14.580644 | K9: 41.368861 | L9: 140.64504 | M9: 51.299076 | N9: 18.269748 | O9: 15.136338 | P9: 54.028674 | Q9: 1130.7547 | R9: 672.06195 | S9: 2012.4368 | T9: 2236.7765 | AP9: 3.9367119 | AQ9: 1.5122846 | AU9: 0.95244575 | AV9: 0.10366981 | AW9: 0.29413665 | AX9: 0.94947872 | AY9: 0.33814911 | AZ9: 0.28015379
A10: CEF0509 | B10: 2005 Honda Odyssey | C10: minivan | D10: Hybrid III | E10: 2120 | F10: 71.251921 | G10: 32.824654 | H10: 69588.266 | I10: 46.631499 | J10: 8.4892 | K10: 20.758259 | L10: 50.375414 | M10: 33.460979 | N10: 11.781508 | O10: 9.350987 | P10: 34.059043 | Q10: 488.40287 | R10: 43.134472 | S10: 968.3573 | T10: 1008.8094 | AP10: 1.5346823 | AQ10: 1.0376055 | AU10: 0.92567972 | AV10: 0.16851871 | AW10: 0.41207123 | AX10: 0.98244038 | AY10: 0.34591424 | AZ10: 0.27455225
A11: CEF0602 | B11: 2006 Kia Sedona | C11: minivan | D11: Hybrid III | E11: 2162 | F11: 73.154695 | G11: 36.332487 | H11: 78550.837 | I11: 50.101208 | J11: 14.73933 | K11: 28.830095 | L11: 56.498432 | M11: 39.60948 | N11: 13.890496 | O11: 16.426584 | P11: 41.831844 | Q11: 552.07166 | R11: 618.70544 | S11: 1178.1046 | T11: 1206.314 | AP11: 1.5550389 | AQ11: 1.151362 | AU11: 0.88677165 | AV11: 0.26088034 | AW11: 0.51028133 | AX11: 0.94687387 | AY11: 0.33205555 | AZ11: 0.39268133
A12: CEF0806 | B12: 2008 Dodge Grand Caravan | C12: minivan | D12: Hybrid III | E12: 2146 | F12: 70.350473 | G12: 36.041588 | H12: 77345.248 | I12: 38.06682 | J12: 27.756984 | K12: 30.570376 | L12: 53.899169 | M12: 42.927129 | N12: 18.33332 | O12: 20.627484 | P12: 47.754998 | Q12: 543.56422 | R12: 824.50719 | S12: 1337.9806 | T12: 1439.0736 | AP12: 1.4954715 | AQ12: 1.3249971 | AU12: 0.70625987 | AV12: 0.51497981 | AW12: 0.56717713 | AX12: 0.89890338 | AY12: 0.38390369 | AZ12: 0.43194398
A13: CEF2315 | B13: 2023 Kia Carnival | C13: minivan | D13: Hybrid III | E13: 2254 | F13: 68.325064 | G13: 29.934559 | H13: 67472.497 | I13: 45.975332 | J13: 7.1115579 | K13: 11.142165 | L13: 47.1888 | M13: 36.860426 | N13: 9.9251437 | O13: 8.2625908 | P13: 37.371195 | Q13: 527.43384 | R13: 88.718836 | S13: 718.18987 | T13: 866.45103 | U13: 93.4106 | V13: 9.7293085 | W13: 74.350827 | X13: 101.09278 | Y13: 36.335635 | Z13: 18.964943 | AA13: 16.323457 | AB13: 42.270802 | AC13: 36.829249 | AD13: 9.2059317 | AE13: 28.29749 | AF13: 42.426224 | AG13: 1323.351 | AH13: 706.4994 | AI13: 2730.0219 | AJ13: 3013.2319 | AK13: 1351.1464 | AL13: 2659.4207 | AM13: 550.58841 | AN13: 2695.0991 | AP13: 1.5763987 | AQ13: 1.2484298 | AR13: 3.3771259 | AS13: 1.412107 | AT13: 1.4172991 | AU13: 0.97428484 | AV13: 0.15070436 | AW13: 0.23611885 | AX13: 0.98633256 | AY13: 0.26558272 | AZ13: 0.22109517 | BA13: 0.92400865 | BB13: 0.096241382 | BC13: 0.73547121 | BD13: 0.85959179 | BE13: 0.44865348 | BF13: 0.38616387 | BG13: 0.86807748 | BH13: 0.21698683 | BI13: 0.66698112
A14: CEF2316 | B14: 2023 Honda Odyssey | C14: minivan | D14: Hybrid III | E14: 2244 | F14: 67.166365 | G14: 32.521814 | H14: 72978.951 | I14: 35.415401 | J14: 19.912317 | K14: 22.266999 | L14: 43.866224 | M14: 40.494537 | N14: 18.544326 | O14: 10.306456 | P14: 45.343906 | Q14: 406.83876 | R14: 244.30456 | S14: 864.91177 | T14: 895.66843 | U14: 45.232414 | V14: 7.3289998 | W14: 85.476907 | X14: 92.625706 | Y14: 47.792294 | Z14: 13.015668 | AA14: 17.960639 | AB14: 51.077107 | AC14: 32.747031 | AD14: 12.690497 | AE14: 29.185379 | AF14: 42.814211 | AG14: 1221.2202 | AH14: 564.67598 | AI14: 3110.3526 | AJ14: 3333.2284 | AK14: 2296.7557 | AL14: 421.39327 | AM14: 2124.3984 | AN14: 2570.1726 | AP14: 1.3488246 | AQ14: 1.3942613 | AR14: 2.8481101 | AS14: 1.5705491 | AT14: 1.3164767 | AU14: 0.80735011 | AV14: 0.45393277 | AW14: 0.50761147 | AX14: 0.89305355 | AY14: 0.40897062 | AZ14: 0.22729528 | BA14: 0.48833543 | BB14: 0.079124901 | BC14: 0.92282057 | BD14: 0.93568914 | BE14: 0.2548239 | BF14: 0.35163776 | BG14: 0.76486358 | BH14: 0.29640851 | BI14: 0.68167504
